Traceback (most recent call last):
  File "/Users/Kaemyui/anaconda3/lib/python3.10/site-packages/jupyter_cache/executors/utils.py", line 58, in single_nb_execution
    executenb(
  File "/Users/Kaemyui/anaconda3/lib/python3.10/site-packages/nbclient/client.py", line 1204, in execute
    return NotebookClient(nb=nb, resources=resources, km=km, **kwargs).execute()
  File "/Users/Kaemyui/anaconda3/lib/python3.10/site-packages/nbclient/util.py", line 84, in wrapped
    return just_run(coro(*args, **kwargs))
  File "/Users/Kaemyui/anaconda3/lib/python3.10/site-packages/nbclient/util.py", line 62, in just_run
    return loop.run_until_complete(coro)
  File "/Users/Kaemyui/anaconda3/lib/python3.10/asyncio/base_events.py", line 649, in run_until_complete
    return future.result()
  File "/Users/Kaemyui/anaconda3/lib/python3.10/site-packages/nbclient/client.py", line 663, in async_execute
    await self.async_execute_cell(
  File "/Users/Kaemyui/anaconda3/lib/python3.10/site-packages/nbclient/client.py", line 965, in async_execute_cell
    await self._check_raise_for_error(cell, cell_index, exec_reply)
  File "/Users/Kaemyui/anaconda3/lib/python3.10/site-packages/nbclient/client.py", line 862, in _check_raise_for_error
    raise CellExecutionError.from_cell_and_msg(cell, exec_reply_content)
nbclient.exceptions.CellExecutionError: An error occurred while executing the following cell:
------------------
%%tikz -S test_output.tikz -f svg
\draw (0,0) rectangle (1,2);
\filldraw (0.5,0.5) circle (.1);
------------------

[0;31m---------------------------------------------------------------------------[0m
[0;31mFileNotFoundError[0m                         Traceback (most recent call last)
Cell [0;32mIn[2], line 1[0m
[0;32m----> 1[0m [43mget_ipython[49m[43m([49m[43m)[49m[38;5;241;43m.[39;49m[43mrun_cell_magic[49m[43m([49m[38;5;124;43m'[39;49m[38;5;124;43mtikz[39;49m[38;5;124;43m'[39;49m[43m,[49m[43m [49m[38;5;124;43m'[39;49m[38;5;124;43m-S test_output.tikz -f svg[39;49m[38;5;124;43m'[39;49m[43m,[49m[43m [49m[38;5;124;43m'[39;49m[38;5;130;43;01m\\[39;49;00m[38;5;124;43mdraw (0,0) rectangle (1,2);[39;49m[38;5;130;43;01m\n[39;49;00m[38;5;130;43;01m\\[39;49;00m[38;5;124;43mfilldraw (0.5,0.5) circle (.1);[39;49m[38;5;130;43;01m\n[39;49;00m[38;5;124;43m'[39;49m[43m)[49m

File [0;32m~/anaconda3/lib/python3.10/site-packages/IPython/core/interactiveshell.py:2430[0m, in [0;36mInteractiveShell.run_cell_magic[0;34m(self, magic_name, line, cell)[0m
[1;32m   2428[0m [38;5;28;01mwith[39;00m [38;5;28mself[39m[38;5;241m.[39mbuiltin_trap:
[1;32m   2429[0m     args [38;5;241m=[39m (magic_arg_s, cell)
[0;32m-> 2430[0m     result [38;5;241m=[39m [43mfn[49m[43m([49m[38;5;241;43m*[39;49m[43margs[49m[43m,[49m[43m [49m[38;5;241;43m*[39;49m[38;5;241;43m*[39;49m[43mkwargs[49m[43m)[49m
[1;32m   2432[0m [38;5;66;03m# The code below prevents the output from being displayed[39;00m
[1;32m   2433[0m [38;5;66;03m# when using magics with decodator @output_can_be_silenced[39;00m
[1;32m   2434[0m [38;5;66;03m# when the last Python token in the expression is a ';'.[39;00m
[1;32m   2435[0m [38;5;28;01mif[39;00m [38;5;28mgetattr[39m(fn, magic[38;5;241m.[39mMAGIC_OUTPUT_CAN_BE_SILENCED, [38;5;28;01mFalse[39;00m):

File [0;32m~/anaconda3/lib/python3.10/site-packages/tikzmagic.py:400[0m, in [0;36mTikzMagics.tikz[0;34m(self, line, cell, local_ns)[0m
[1;32m    398[0m [38;5;66;03m# Copy output file if requested[39;00m
[1;32m    399[0m [38;5;28;01mif[39;00m args[38;5;241m.[39msave [38;5;129;01mis[39;00m [38;5;129;01mnot[39;00m [38;5;28;01mNone[39;00m:
[0;32m--> 400[0m     [43mcopy[49m[43m([49m[43mimage_filename[49m[43m,[49m[43m [49m[43margs[49m[38;5;241;43m.[39;49m[43msave[49m[43m)[49m
[1;32m    402[0m rmtree(plot_dir)
[1;32m    404[0m [38;5;28;01mfor[39;00m tag, disp_d [38;5;129;01min[39;00m display_data:

File [0;32m~/anaconda3/lib/python3.10/shutil.py:417[0m, in [0;36mcopy[0;34m(src, dst, follow_symlinks)[0m
[1;32m    415[0m [38;5;28;01mif[39;00m os[38;5;241m.[39mpath[38;5;241m.[39misdir(dst):
[1;32m    416[0m     dst [38;5;241m=[39m os[38;5;241m.[39mpath[38;5;241m.[39mjoin(dst, os[38;5;241m.[39mpath[38;5;241m.[39mbasename(src))
[0;32m--> 417[0m [43mcopyfile[49m[43m([49m[43msrc[49m[43m,[49m[43m [49m[43mdst[49m[43m,[49m[43m [49m[43mfollow_symlinks[49m[38;5;241;43m=[39;49m[43mfollow_symlinks[49m[43m)[49m
[1;32m    418[0m copymode(src, dst, follow_symlinks[38;5;241m=[39mfollow_symlinks)
[1;32m    419[0m [38;5;28;01mreturn[39;00m dst

File [0;32m~/anaconda3/lib/python3.10/shutil.py:254[0m, in [0;36mcopyfile[0;34m(src, dst, follow_symlinks)[0m
[1;32m    252[0m     os[38;5;241m.[39msymlink(os[38;5;241m.[39mreadlink(src), dst)
[1;32m    253[0m [38;5;28;01melse[39;00m:
[0;32m--> 254[0m     [38;5;28;01mwith[39;00m [38;5;28;43mopen[39;49m[43m([49m[43msrc[49m[43m,[49m[43m [49m[38;5;124;43m'[39;49m[38;5;124;43mrb[39;49m[38;5;124;43m'[39;49m[43m)[49m [38;5;28;01mas[39;00m fsrc:
[1;32m    255[0m         [38;5;28;01mtry[39;00m:
[1;32m    256[0m             [38;5;28;01mwith[39;00m [38;5;28mopen[39m(dst, [38;5;124m'[39m[38;5;124mwb[39m[38;5;124m'[39m) [38;5;28;01mas[39;00m fdst:
[1;32m    257[0m                 [38;5;66;03m# macOS[39;00m

[0;31mFileNotFoundError[0m: [Errno 2] No such file or directory: '/var/folders/1s/4ndng0l11_s0dxtqj995xwr40000gn/T/tmp7k2eyj2q/tikz.svg'
FileNotFoundError: [Errno 2] No such file or directory: '/var/folders/1s/4ndng0l11_s0dxtqj995xwr40000gn/T/tmp7k2eyj2q/tikz.svg'

