Traceback (most recent call last):
  File "/Users/Kaemyui/anaconda3/lib/python3.10/site-packages/jupyter_cache/executors/utils.py", line 58, in single_nb_execution
    executenb(
  File "/Users/Kaemyui/anaconda3/lib/python3.10/site-packages/nbclient/client.py", line 1204, in execute
    return NotebookClient(nb=nb, resources=resources, km=km, **kwargs).execute()
  File "/Users/Kaemyui/anaconda3/lib/python3.10/site-packages/nbclient/util.py", line 84, in wrapped
    return just_run(coro(*args, **kwargs))
  File "/Users/Kaemyui/anaconda3/lib/python3.10/site-packages/nbclient/util.py", line 62, in just_run
    return loop.run_until_complete(coro)
  File "/Users/Kaemyui/anaconda3/lib/python3.10/asyncio/base_events.py", line 649, in run_until_complete
    return future.result()
  File "/Users/Kaemyui/anaconda3/lib/python3.10/site-packages/nbclient/client.py", line 663, in async_execute
    await self.async_execute_cell(
  File "/Users/Kaemyui/anaconda3/lib/python3.10/site-packages/nbclient/client.py", line 965, in async_execute_cell
    await self._check_raise_for_error(cell, cell_index, exec_reply)
  File "/Users/Kaemyui/anaconda3/lib/python3.10/site-packages/nbclient/client.py", line 862, in _check_raise_for_error
    raise CellExecutionError.from_cell_and_msg(cell, exec_reply_content)
nbclient.exceptions.CellExecutionError: An error occurred while executing the following cell:
------------------
suppressMessages(library(CASdatasets))

data(freMTPL2freq)
------------------

Error in library(CASdatasets): there is no package called ‘CASdatasets’
Traceback:

1. suppressMessages(library(CASdatasets))
2. withCallingHandlers(expr, message = function(c) if (inherits(c, 
 .     classes)) tryInvokeRestart("muffleMessage"))
3. library(CASdatasets)
ERROR: Error in library(CASdatasets): there is no package called ‘CASdatasets’


